<?xml version="1.0" encoding="utf-8"?>
<robot name="atom01urdf">
  <link name="base_link">
    <inertial>
      <origin xyz="-0.04700769 -0.00000239 -0.00862801" rpy="0 0 0"/>
      <mass value="5.51295532"/>
      <inertia ixx="0.03052646" ixy="0.00000063" ixz="-0.00079063" iyy="0.01536233" iyz="0.00000026" izz="0.03006209"/>
    </inertial>
    <visual>
      <origin xyz="0 0 0" rpy="0 0 0"/>
      <geometry>
        <mesh filename="../meshes/base_link.STL"/>
      </geometry>
      <material name="">
        <color rgba="0.898039215686275 0.917647058823529 0.929411764705882 1"/>
      </material>
    </visual>
    <collision>
      <origin xyz="0 0 0" rpy="0 0 0"/>
      <geometry>
        <mesh filename="../meshes/base_link.STL"/>
      </geometry>
    </collision>
  </link>
  <link name="left_thigh_yaw_link">
    <inertial>
      <origin xyz="-0.03847656 -0.0000142 -0.05612329" rpy="0 0 0"/>
      <mass value="1.71784575"/>
      <inertia ixx="0.00319789" ixy="0.00000025" ixz="-0.00065088" iyy="0.0024412" iyz="0.00000117" izz="0.00251651"/>
    </inertial>
    <visual>
      <origin xyz="0 0 0" rpy="0 0 0"/>
      <geometry>
        <mesh filename="../meshes/left_thigh_yaw_link.STL"/>
      </geometry>
      <material name="">
        <color rgba="0.898039215686275 0.917647058823529 0.929411764705882 1"/>
      </material>
    </visual>
    <!-- <collision>
      <origin
        xyz="0 0 0"
        rpy="0 0 0" />
      <geometry>
        <mesh
          filename="../meshes/left_thigh_yaw_link.STL" />
      </geometry>
    </collision> -->
  </link>
  <joint name="left_thigh_yaw_joint" type="revolute">
    <origin xyz="-0.071093 0.0725 -0.051778" rpy="0 0 0"/>
    <parent link="base_link"/>
    <child link="left_thigh_yaw_link"/>
    <axis xyz="-0.5 0 -0.86603"/>
    <limit lower="-1" upper="0.2" effort="120" velocity="25.0"/>
  </joint>
  <link name="left_thigh_roll_link">
    <inertial>
      <origin xyz="0.05748778 -0.00601901 -0.03308921" rpy="0 0 0"/>
      <mass value="1.66236465"/>
      <inertia ixx="0.00212675" ixy="0.00003170" ixz="0.00014062" iyy="0.00351120" iyz="-0.00001801" izz="0.00228565"/>
    </inertial>
    <visual>
      <origin xyz="0 0 0" rpy="0 0 0"/>
      <geometry>
        <mesh filename="../meshes/left_thigh_roll_link.STL"/>
      </geometry>
      <material name="">
        <color rgba="0.752941176470588 0.752941176470588 0.752941176470588 1"/>
      </material>
    </visual>
    <!-- <collision>
      <origin
        xyz="0 0 0"
        rpy="0 0 0" />
      <geometry>
        <mesh
          filename="../meshes/left_thigh_roll_link.STL" />
      </geometry>
    </collision> -->
  </link>
  <joint name="left_thigh_roll_joint" type="revolute">
    <origin xyz="-0.017693 0 -0.072346" rpy="0 0 0"/>
    <parent link="left_thigh_yaw_link"/>
    <child link="left_thigh_roll_link"/>
    <axis xyz="0.86603 0 -0.5"/>
    <limit lower="-0.2" upper="1" effort="120" velocity="25.0"/>
  </joint>
  <link name="left_thigh_pitch_link">
    <inertial>
      <origin xyz="0.00004587 -0.01904764 -0.19858149" rpy="0 0 0"/>
      <mass value="2.34600715"/>
      <inertia ixx="0.02018963" ixy="-0.00000310" ixz="0.00001430" iyy="0.02158818" iyz="-0.00215090" izz="0.00302937"/>
    </inertial>
    <visual>
      <origin xyz="0 0 0" rpy="0 0 0"/>
      <geometry>
        <mesh filename="../meshes/left_thigh_pitch_link.STL"/>
      </geometry>
      <material name="">
        <color rgba="0.898039215686275 0.917647058823529 0.929411764705882 1"/>
      </material>
    </visual>
    <!-- <collision>
      <origin
        xyz="0 0 0"
        rpy="0 0 0" />
      <geometry>
        <mesh
          filename="../meshes/left_thigh_pitch_link.STL" />
      </geometry>
    </collision> -->
    <collision>
      <origin xyz="0.0 -0.02 -0.08" rpy="0 0 0"/>
      <geometry>
        <box size="0.08 0.12 0.22"/>
      </geometry>
    </collision>
  </link>
  <joint name="left_thigh_pitch_joint" type="revolute">
    <origin xyz="0.060622 0.02085 -0.035" rpy="0 0 0"/>
    <parent link="left_thigh_roll_link"/>
    <child link="left_thigh_pitch_link"/>
    <axis xyz="0 1 0"/>
    <limit lower="-1.57" upper="1.57" effort="120" velocity="25.0"/>
  </joint>
  <link name="left_knee_link">
    <inertial>
      <origin xyz="-0.00035292 -0.0132798 -0.15208271" rpy="0 0 0"/>
      <mass value="1.70223945"/>
      <inertia ixx="0.01013470" ixy="0.00002119" ixz="0.00003224" iyy="0.00981975" iyz="-0.00022577" izz="0.00110105"/>
    </inertial>
    <visual>
      <origin xyz="0 0 0" rpy="0 0 0"/>
      <geometry>
        <mesh filename="../meshes/left_knee_link.STL"/>
      </geometry>
      <material name="">
        <color rgba="0.898039215686275 0.917647058823529 0.929411764705882 1"/>
      </material>
    </visual>
    <!-- <collision>
      <origin
        xyz="0 0 0"
        rpy="0 0 0" />
      <geometry>
        <mesh
          filename="../meshes/left_knee_link.STL" />
      </geometry>
    </collision> -->
    <collision>
      <origin xyz="0.0 -0.02 -0.1" rpy="0 0 0"/>
      <geometry>
        <box size="0.08 0.12 0.25"/>
      </geometry>
    </collision>
  </link>
  <joint name="left_knee_joint" type="revolute">
    <origin xyz="0 0 -0.25" rpy="0 0 0"/>
    <parent link="left_thigh_pitch_link"/>
    <child link="left_knee_link"/>
    <axis xyz="0 1 0"/>
    <limit lower="-0.2" upper="2.5" effort="120" velocity="25.0"/>
  </joint>
  <link name="left_ankle_pitch_link">
    <inertial>
      <origin xyz="0.0 0.0 0.0" rpy="0 0 0"/>
      <mass value="0.084"/>
      <inertia ixx="0.00000863" ixy="0.0" ixz="0.0" iyy="0.00000863" iyz="0.0" izz="0.00001448"/>
    </inertial>
    <visual>
      <origin xyz="0 0 0" rpy="0 0 0"/>
      <geometry>
        <mesh filename="../meshes/left_ankle_pitch_link.STL"/>
      </geometry>
      <material name="">
        <color rgba="1 1 1 1"/>
      </material>
    </visual>
    <!-- <collision>
      <origin
        xyz="0 0 0"
        rpy="0 0 0" />
      <geometry>
        <mesh
          filename="../meshes/left_ankle_pitch_link.STL" />
      </geometry>
    </collision> -->
  </link>
  <joint name="left_ankle_pitch_joint" type="revolute">
    <origin xyz="0 -0.02085 -0.3" rpy="0 0 0"/>
    <parent link="left_knee_link"/>
    <child link="left_ankle_pitch_link"/>
    <axis xyz="0 1 0"/>
    <limit lower="-0.6" upper="0.6" effort="27" velocity="8.0"/>
  </joint>
  <link name="left_ankle_roll_link">
    <inertial>
      <origin xyz="0.01454282 0.00284825 -0.02908608" rpy="0 0 0"/>
      <mass value="0.33517651"/>
      <inertia ixx="0.00013432" ixy="0.00001389" ixz="0.00002909" iyy="0.00054303" iyz="-0.00001883" izz="0.00058883"/>
    </inertial>
    <visual>
      <origin xyz="0 0 0" rpy="0 0 0"/>
      <geometry>
        <mesh filename="../meshes/left_ankle_roll_link.STL"/>
      </geometry>
      <material name="">
        <color rgba="0.898039215686275 0.917647058823529 0.929411764705882 1"/>
      </material>
    </visual>
    <collision>
      <origin xyz="0 0 0" rpy="0 0 0"/>
      <geometry>
        <mesh filename="../meshes/left_ankle_roll_link.STL"/>
      </geometry>
    </collision>
  </link>
  <joint name="left_ankle_roll_joint" type="revolute">
    <origin xyz="0 0 0" rpy="0 0 0"/>
    <parent link="left_ankle_pitch_link"/>
    <child link="left_ankle_roll_link"/>
    <axis xyz="1 0 0"/>
    <limit lower="-0.5" upper="0.5" effort="27" velocity="8.0"/>
  </joint>
  <link name="right_thigh_yaw_link">
    <inertial>
      <origin xyz="-0.03847656 0.0000142 -0.05612329" rpy="0 0 0"/>
      <mass value="1.71632614"/>
      <inertia ixx="0.00319396" ixy="0.0" ixz="-0.00065014" iyy="0.0024375" iyz="-0.00000003" izz="0.00251592"/>
    </inertial>
    <visual>
      <origin xyz="0 0 0" rpy="0 0 0"/>
      <geometry>
        <mesh filename="../meshes/right_thigh_yaw_link.STL"/>
      </geometry>
      <material name="">
        <color rgba="0.898039215686275 0.917647058823529 0.929411764705882 1"/>
      </material>
    </visual>
    <!-- <collision>
      <origin
        xyz="0 0 0"
        rpy="0 0 0" />
      <geometry>
        <mesh
          filename="../meshes/right_thigh_yaw_link.STL" />
      </geometry>
    </collision> -->
  </link>
  <joint name="right_thigh_yaw_joint" type="revolute">
    <origin xyz="-0.071093 -0.0725 -0.051778" rpy="0 0 0"/>
    <parent link="base_link"/>
    <child link="right_thigh_yaw_link"/>
    <axis xyz="-0.5 0 -0.86603"/>
    <limit lower="-0.2" upper="1" effort="120" velocity="25.0"/>
  </joint>
  <link name="right_thigh_roll_link">
    <inertial>
      <origin xyz="0.05748778 0.00601901 -0.03308921" rpy="0 0 0"/>
      <mass value="1.66310652"/>
      <inertia ixx="0.00213051" ixy="-0.00003033" ixz="0.00013508" iyy="0.00351195" iyz="0.00001792" izz="0.00228331"/>
    </inertial>
    <visual>
      <origin xyz="0 0 0" rpy="0 0 0"/>
      <geometry>
        <mesh filename="../meshes/right_thigh_roll_link.STL"/>
      </geometry>
      <material name="">
        <color rgba="0.898039215686275 0.917647058823529 0.929411764705882 1"/>
      </material>
    </visual>
    <!-- <collision>
      <origin
        xyz="0 0 0"
        rpy="0 0 0" />
      <geometry>
        <mesh
          filename="../meshes/right_thigh_roll_link.STL" />
      </geometry>
    </collision> -->
  </link>
  <joint name="right_thigh_roll_joint" type="revolute">
    <origin xyz="-0.0189924084475403 0 -0.0715958163677252" rpy="0 0 0"/>
    <parent link="right_thigh_yaw_link"/>
    <child link="right_thigh_roll_link"/>
    <axis xyz="0.86603 0 -0.5"/>
    <limit lower="-1" upper="0.2" effort="120" velocity="25.0"/>
  </joint>
  <link name="right_thigh_pitch_link">
    <inertial>
      <origin xyz="0.00004587 0.01904764 -0.19858149" rpy="0 0 0"/>
      <mass value="2.34600715"/>
      <inertia ixx="0.02018963" ixy="0.00000309" ixz="0.00001431" iyy="0.02158818" iyz="0.0021509" izz="0.00302937"/>
    </inertial>
    <visual>
      <origin xyz="0 0 0" rpy="0 0 0"/>
      <geometry>
        <mesh filename="../meshes/right_thigh_pitch_link.STL"/>
      </geometry>
      <material name="">
        <color rgba="0.898039215686275 0.917647058823529 0.929411764705882 1"/>
      </material>
    </visual>
    <!-- <collision>
      <origin
        xyz="0 0 0"
        rpy="0 0 0" />
      <geometry>
        <mesh
          filename="../meshes/right_thigh_pitch_link.STL" />
      </geometry>
    </collision> -->
    <collision>
      <origin xyz="0.0 0.02 -0.08" rpy="0 0 0"/>
      <geometry>
        <box size="0.08 0.12 0.22"/>
      </geometry>
    </collision>
  </link>
  <joint name="right_thigh_pitch_joint" type="revolute">
    <origin xyz="0.0619208163652291 -0.0208499999999942 -0.0357500000093095" rpy="0 0 0"/>
    <parent link="right_thigh_roll_link"/>
    <child link="right_thigh_pitch_link"/>
    <axis xyz="0 1 0"/>
    <limit lower="-1.57" upper="1.57" effort="120" velocity="25.0"/>
  </joint>
  <link name="right_knee_link">
    <inertial>
      <origin xyz="-0.00035292 0.0132798 -0.15208271" rpy="0 0 0"/>
      <mass value="1.70223945"/>
      <inertia ixx="0.0101347" ixy="0.00002119" ixz="-0.00003224" iyy="0.00981975" iyz="0.00022577" izz="0.00110105"/>
    </inertial>
    <visual>
      <origin xyz="0 0 0" rpy="0 0 0"/>
      <geometry>
        <mesh filename="../meshes/right_knee_link.STL"/>
      </geometry>
      <material name="">
        <color rgba="0.898039215686275 0.917647058823529 0.929411764705882 1"/>
      </material>
    </visual>
    <!-- <collision>
      <origin
        xyz="0 0 0"
        rpy="0 0 0" />
      <geometry>
        <mesh
          filename="../meshes/right_knee_link.STL" />
      </geometry>
    </collision> -->
    <collision>
      <origin xyz="0.0 0.02 -0.1" rpy="0 0 0"/>
      <geometry>
        <box size="0.08 0.12 0.25"/>
      </geometry>
    </collision>
  </link>
  <joint name="right_knee_joint" type="revolute">
    <origin xyz="0 0 -0.250000000000016" rpy="0 0 0"/>
    <parent link="right_thigh_pitch_link"/>
    <child link="right_knee_link"/>
    <axis xyz="0 1 0"/>
    <limit lower="-0.2" upper="2.5" effort="120" velocity="25.0"/>
  </joint>
  <link name="right_ankle_pitch_link">
    <inertial>
      <origin xyz="0.0 0.0 0.0" rpy="0 0 0"/>
      <mass value="0.084"/>
      <inertia ixx="0.00000863" ixy="0.0" ixz="0.0" iyy="0.00000863" iyz="0.0" izz="0.00001448"/>
    </inertial>
    <visual>
      <origin xyz="0 0 0" rpy="0 0 0"/>
      <geometry>
        <mesh filename="../meshes/right_ankle_pitch_link.STL"/>
      </geometry>
      <material name="">
        <color rgba="1 1 1 1"/>
      </material>
    </visual>
    <!-- <collision>
      <origin
        xyz="0 0 0"
        rpy="0 0 0" />
      <geometry>
        <mesh
          filename="../meshes/right_ankle_pitch_link.STL" />
      </geometry>
    </collision> -->
  </link>
  <joint name="right_ankle_pitch_joint" type="revolute">
    <origin xyz="0 0.0208500000000073 -0.299999999999986" rpy="0 0 0"/>
    <parent link="right_knee_link"/>
    <child link="right_ankle_pitch_link"/>
    <axis xyz="0 1 0"/>
    <limit lower="-0.6" upper="0.6" effort="27" velocity="8.0"/>
  </joint>
  <link name="right_ankle_roll_link">
    <inertial>
      <origin xyz="0.01454282 -0.00284825 -0.02908608" rpy="0 0 0"/>
      <mass value="0.33517651"/>
      <inertia ixx="0.00013432" ixy="-0.00001388" ixz="0.00002909" iyy="0.00054303" iyz="0.00001883" izz="0.00058883"/>
    </inertial>
    <visual>
      <origin xyz="0 0 0" rpy="0 0 0"/>
      <geometry>
        <mesh filename="../meshes/right_ankle_roll_link.STL"/>
      </geometry>
      <material name="">
        <color rgba="0.898039215686275 0.917647058823529 0.929411764705882 1"/>
      </material>
    </visual>
    <collision>
      <origin xyz="0 0 0" rpy="0 0 0"/>
      <geometry>
        <mesh filename="../meshes/right_ankle_roll_link.STL"/>
      </geometry>
    </collision>
  </link>
  <joint name="right_ankle_roll_joint" type="revolute">
    <origin xyz="0 0 0" rpy="0 0 0"/>
    <parent link="right_ankle_pitch_link"/>
    <child link="right_ankle_roll_link"/>
    <axis xyz="1 0 0"/>
    <limit lower="-0.5" upper="0.5" effort="27" velocity="8.0"/>
  </joint>
  <link name="torso_link">
    <inertial>
      <origin xyz="-0.00234775 -0.00000466 0.0984446" rpy="0 0 0"/>
      <mass value="7.58189737"/>
      <inertia ixx="0.06904132" ixy="-0.00004044" ixz="0.00223305" iyy="0.05679531" iyz="-0.00001881" izz="0.03888628"/>
    </inertial>
    <visual>
      <origin xyz="0 0 0" rpy="0 0 0"/>
      <geometry>
        <mesh filename="../meshes/torso_link.STL"/>
      </geometry>
      <material name="">
        <color rgba="1 1 1 1"/>
      </material>
    </visual>
    <collision>
      <origin xyz="0 0 0.15" rpy="0 0 0"/>
      <geometry>
        <box size="0.16 0.16 0.22"/>
      </geometry>
    </collision>
  </link>
  <joint name="torso_joint" type="revolute">
    <origin xyz="-0.0281649492242451 0 0.0672000000054882" rpy="0 0 0"/>
    <parent link="base_link"/>
    <child link="torso_link"/>
    <axis xyz="0 0 1"/>
    <limit lower="-3.14" upper="3.14" effort="120" velocity="25.0"/>
  </joint>
  <link name="left_arm_pitch_link">
    <inertial>
      <origin xyz="-0.00436523 0.04995146 0.0" rpy="0 0 0"/>
      <mass value="0.47284363"/>
      <inertia ixx="0.00015644" ixy="0.00002207" ixz="0.0" iyy="0.00008197" iyz="0.0" izz="0.00018907"/>
    </inertial>
    <visual>
      <origin xyz="0 0 0" rpy="0 0 0"/>
      <geometry>
        <mesh filename="../meshes/left_arm_pitch_link.STL"/>
      </geometry>
      <material name="">
        <color rgba="0.796078431372549 0.823529411764706 0.937254901960784 1"/>
      </material>
    </visual>
    <collision>
      <origin xyz="0 0.055 0" rpy="0 1.57 0"/>
      <geometry>
        <cylinder radius="0.03" length="0.05"/>
      </geometry>
    </collision>
  </link>
  <joint name="left_arm_pitch_joint" type="revolute">
    <origin xyz="0 0.121749999999383 0.206175860782433" rpy="0 0 0"/>
    <parent link="torso_link"/>
    <child link="left_arm_pitch_link"/>
    <axis xyz="0 1 0"/>
    <limit lower="-3.14" upper="1.57" effort="27" velocity="8.0"/>
  </joint>
  <link name="left_arm_roll_link">
    <inertial>
      <origin xyz="-0.0029007 0.0 -0.02197112" rpy="0 0 0"/>
      <mass value="0.08401883"/>
      <inertia ixx="0.00004601" ixy="0.0" ixz="-0.00001743" iyy="0.00005649" iyz="0.0" izz="0.00002712"/>
    </inertial>
    <visual>
      <origin xyz="0 0 0" rpy="0 0 0"/>
      <geometry>
        <mesh filename="../meshes/left_arm_roll_link.STL"/>
      </geometry>
      <material name="">
        <color rgba="0.796078431372549 0.823529411764706 0.937254901960784 1"/>
      </material>
    </visual>
    <collision>
      <origin xyz="-0.02 0 -0.12" rpy="0 0 0"/>
      <geometry>
        <cylinder radius="0.03" length="0.10"/>
      </geometry>
    </collision>
  </link>
  <joint name="left_arm_roll_joint" type="revolute">
    <origin xyz="0.0200000000000018 0.056 0" rpy="0 0 0"/>
    <parent link="left_arm_pitch_link"/>
    <child link="left_arm_roll_link"/>
    <axis xyz="1 0 0"/>
    <limit lower="-0.25" upper="3.14" effort="27" velocity="8.0"/>
  </joint>
  <link name="left_arm_yaw_link">
    <inertial>
      <origin xyz="-0.00004328 -0.0018211 -0.10615895" rpy="0 0 0"/>
      <mass value="1.15324354"/>
      <inertia ixx="0.00619553" ixy="-0.00000002" ixz="-0.00000077" iyy="0.00615816" iyz="-0.0001812" izz="0.0003308"/>
    </inertial>
    <visual>
      <origin xyz="0 0 0" rpy="0 0 0"/>
      <geometry>
        <mesh filename="../meshes/left_arm_yaw_link.STL"/>
      </geometry>
      <material name="">
        <color rgba="0.796078431372549 0.823529411764706 0.937254901960784 1"/>
      </material>
    </visual>
    <collision>
      <origin xyz="0 0 -0.19" rpy="0 1.57 1.57"/>
      <geometry>
        <cylinder radius="0.03" length="0.05"/>
      </geometry>
    </collision>
  </link>
  <joint name="left_arm_yaw_joint" type="revolute">
    <origin xyz="-0.0200000000000002 0 -0.049999999999998" rpy="0 0 0"/>
    <parent link="left_arm_roll_link"/>
    <child link="left_arm_yaw_link"/>
    <axis xyz="0 0 -1"/>
    <limit lower="-1.57" upper="1.57" effort="27" velocity="8.0"/>
  </joint>
  <link name="left_elbow_pitch_link">
    <inertial>
      <origin xyz="0.02378501 -0.00433076 0.0" rpy="0 0 0"/>
      <mass value="0.09168684"/>
      <inertia ixx="0.00003059" ixy="0.00002004" ixz="0.0" iyy="0.00005023" iyz="0.0" izz="0.00006277"/>
    </inertial>
    <visual>
      <origin xyz="0 0 0" rpy="0 0 0"/>
      <geometry>
        <mesh filename="../meshes/left_elbow_pitch_link.STL"/>
      </geometry>
      <material name="">
        <color rgba="0.796078431372549 0.823529411764706 0.937254901960784 1"/>
      </material>
    </visual>
    <collision>
      <origin xyz="0.14 -0.02 0" rpy="0 1.57 0"/>
      <geometry>
        <cylinder radius="0.03" length="0.10"/>
      </geometry>
    </collision>
  </link>
  <joint name="left_elbow_pitch_joint" type="revolute">
    <origin xyz="0 0.0199999999999982 -0.188749999999997" rpy="0 0 0"/>
    <parent link="left_arm_yaw_link"/>
    <child link="left_elbow_pitch_link"/>
    <axis xyz="0 1 0"/>
    <limit lower="-0.6" upper="1.57" effort="27" velocity="8.0"/>
  </joint>
  <link name="left_elbow_yaw_link">
    <inertial>
      <origin xyz="0.05317619 -0.0000345 -0.00001992" rpy="0 0 0"/>
      <mass value="0.68145595"/>
      <inertia ixx="0.00024481" ixy="-0.00000008" ixz="-0.00000014" iyy="0.00132562" iyz="-0.0000006" izz="0.00132647"/>
    </inertial>
    <visual>
      <origin xyz="0 0 0" rpy="0 0 0"/>
      <geometry>
        <mesh filename="../meshes/left_elbow_yaw_link.STL"/>
      </geometry>
      <material name="">
        <color rgba="0.796078431372549 0.823529411764706 0.937254901960784 1"/>
      </material>
    </visual>
    <!-- <collision>
      <origin
        xyz="0 0 0"
        rpy="0 0 0" />
      <geometry>
        <mesh
          filename="../meshes/left_elbow_yaw_link.STL" />
      </geometry>
    </collision> -->
  </link>
  <joint name="left_elbow_yaw_joint" type="revolute">
    <origin xyz="0.0499999999999968 -0.0199999999999994 0" rpy="0 0 0"/>
    <parent link="left_elbow_pitch_link"/>
    <child link="left_elbow_yaw_link"/>
    <axis xyz="1 0 0"/>
    <limit lower="-1.57" upper="1.57" effort="27" velocity="8.0"/>
  </joint>
  <link name="right_arm_pitch_link">
    <inertial>
      <origin xyz="-0.00436523 -0.04995146 0.0" rpy="0 0 0"/>
      <mass value="0.47284363"/>
      <inertia ixx="0.00015644" ixy="-0.00002207" ixz="0.0" iyy="0.00008197" iyz="0.0" izz="0.00018907"/>
    </inertial>
    <visual>
      <origin xyz="0 0 0" rpy="0 0 0"/>
      <geometry>
        <mesh filename="../meshes/right_arm_pitch_link.STL"/>
      </geometry>
      <material name="">
        <color rgba="1 1 1 1"/>
      </material>
    </visual>
    <collision>
      <origin xyz="0 -0.055 0" rpy="0 1.57 0"/>
      <geometry>
        <cylinder radius="0.03" length="0.05"/>
      </geometry>
    </collision>
  </link>
  <joint name="right_arm_pitch_joint" type="revolute">
    <origin xyz="0 -0.121750000000346 0.206175860781721" rpy="0 0 0"/>
    <parent link="torso_link"/>
    <child link="right_arm_pitch_link"/>
    <axis xyz="0 1 0"/>
    <limit lower="-3.14" upper="1.57" effort="27" velocity="8.0"/>
  </joint>
  <link name="right_arm_roll_link">
    <inertial>
      <origin xyz="-0.0029007 0.0 -0.02197112" rpy="0 0 0"/>
      <mass value="0.08401883"/>
      <inertia ixx="0.00004601" ixy="0.0" ixz="-0.00001743" iyy="0.00005649" iyz="0.0" izz="0.00002712"/>
    </inertial>
    <visual>
      <origin xyz="0 0 0" rpy="0 0 0"/>
      <geometry>
        <mesh filename="../meshes/right_arm_roll_link.STL"/>
      </geometry>
      <material name="">
        <color rgba="0.796078431372549 0.823529411764706 0.937254901960784 1"/>
      </material>
    </visual>
    <collision>
      <origin xyz="-0.02 0 -0.12" rpy="0 0 0"/>
      <geometry>
        <cylinder radius="0.03" length="0.10"/>
      </geometry>
    </collision>
  </link>
  <joint name="right_arm_roll_joint" type="revolute">
    <origin xyz="0.0200000000000407 -0.056 0" rpy="0 0 0"/>
    <parent link="right_arm_pitch_link"/>
    <child link="right_arm_roll_link"/>
    <axis xyz="1 0 0"/>
    <limit lower="-3.14" upper="0.25" effort="27" velocity="8.0"/>
  </joint>
  <link name="right_arm_yaw_link">
    <inertial>
      <origin xyz="-0.00004328 0.0018211 -0.10615895" rpy="0 0 0"/>
      <mass value="1.15429959"/>
      <inertia ixx="0.0062043" ixy="0.00000007" ixz="-0.00000008" iyy="0.00616498" iyz="0.00017831" izz="0.00033199"/>
    </inertial>
    <visual>
      <origin xyz="0 0 0" rpy="0 0 0"/>
      <geometry>
        <mesh filename="../meshes/right_arm_yaw_link.STL"/>
      </geometry>
      <material name="">
        <color rgba="0.796078431372549 0.823529411764706 0.937254901960784 1"/>
      </material>
    </visual>
    <collision>
      <origin xyz="0 0 -0.19" rpy="0 1.57 1.57"/>
      <geometry>
        <cylinder radius="0.03" length="0.05"/>
      </geometry>
    </collision>
  </link>
  <joint name="right_arm_yaw_joint" type="revolute">
    <origin xyz="-0.02 0 -0.0500000000000019" rpy="0 0 0"/>
    <parent link="right_arm_roll_link"/>
    <child link="right_arm_yaw_link"/>
    <axis xyz="0 0 -1"/>
    <limit lower="-1.57" upper="1.57" effort="27" velocity="8.0"/>
  </joint>
  <link name="right_elbow_pitch_link">
    <inertial>
      <origin xyz="0.02378501 0.00433076 0.0" rpy="0 0 0"/>
      <mass value="0.09168684"/>
      <inertia ixx="0.00003059" ixy="-0.00002004" ixz="0.0" iyy="0.00005023" iyz="0.0" izz="0.00006277"/>
    </inertial>
    <visual>
      <origin xyz="0 0 0" rpy="0 0 0"/>
      <geometry>
        <mesh filename="../meshes/right_elbow_pitch_link.STL"/>
      </geometry>
      <material name="">
        <color rgba="0.796078431372549 0.823529411764706 0.937254901960784 1"/>
      </material>
    </visual>
    <collision>
      <origin xyz="0.14 0.02 0" rpy="0 1.57 0"/>
      <geometry>
        <cylinder radius="0.03" length="0.10"/>
      </geometry>
    </collision>
  </link>
  <joint name="right_elbow_pitch_joint" type="revolute">
    <origin xyz="0 -0.0200000000000019 -0.18875" rpy="0 0 0"/>
    <parent link="right_arm_yaw_link"/>
    <child link="right_elbow_pitch_link"/>
    <axis xyz="0 1 0"/>
    <limit lower="-0.6" upper="1.57" effort="27" velocity="8.0"/>
  </joint>
  <link name="right_elbow_yaw_link">
    <inertial>
      <origin xyz="0.05317619 0.0000345 -0.00001992" rpy="0 0 0"/>
      <mass value="0.68145595"/>
      <inertia ixx="0.00024481" ixy="0.00000008" ixz="0.00000014" iyy="0.00132562" iyz="-0.0000006" izz="0.00132647"/>
    </inertial>
    <visual>
      <origin xyz="0 0 0" rpy="0 0 0"/>
      <geometry>
        <mesh filename="../meshes/right_elbow_yaw_link.STL"/>
      </geometry>
      <material name="">
        <color rgba="1 1 1 1"/>
      </material>
    </visual>
    <!-- <collision>
      <origin
        xyz="0 0 0"
        rpy="0 0 0" />
      <geometry>
        <mesh
          filename="../meshes/right_elbow_yaw_link.STL" />
      </geometry>
    </collision> -->
  </link>
  <joint name="right_elbow_yaw_joint" type="revolute">
    <origin xyz="0.0500000000000002 0.0200000000000004 0" rpy="0 0 0"/>
    <parent link="right_elbow_pitch_link"/>
    <child link="right_elbow_yaw_link"/>
    <axis xyz="1 0 0"/>
    <limit lower="-1.57" upper="1.57" effort="27" velocity="8.0"/>
  </joint>
</robot>
