<?xml version="1.0"?>
<mujoco model="atom01">
  <compiler angle="radian" meshdir="../meshes/" eulerseq="zyx"/>
  <option timestep="0.001" iterations="100" solver="PGS" gravity="0 0 -9.81">
    <flag frictionloss="enable"/>
  </option>
  <size njmax="500" nconmax="100"/>
  <visual>
    <quality shadowsize="4096"/>
    <map znear="0.05"/>
  </visual>
  <default>
    <joint limited="true"/>
    <motor ctrllimited="true"/>
    <geom condim="4" contype="1" conaffinity="15" solref="0.001 2" friction="0.9 0.2 0.2" group="1"/>
    <equality solref="0.001 2"/>
    <default class="visualgeom">
      <geom material="visualgeom" condim="1" contype="0" conaffinity="0"/>
    </default>
    <default class="obstacle">
      <geom material="obstacle" condim="3" contype="1" conaffinity="15"/>
    </default>
    <default class="waist_joint_param">
      <joint damping="0.01" frictionloss="0.01" armature="0.01"/>
    </default>
    <default class="leg_joint_param">
      <joint damping="0.01" frictionloss="0.01" armature="0.01"/>
    </default>
    <default class="arm_joint_param">
      <joint damping="0.01" frictionloss="0.01" armature="0.01"/>
    </default>
  </default>
  <asset>
    <texture type="skybox" builtin="gradient" rgb1="0.3 0.5 0.7" rgb2="0 0 0" width="512" height="512"/>
    <texture name="texplane" type="2d" builtin="checker" rgb1=".2 .3 .4" rgb2=".1 0.15 0.2" width="512" height="512" mark="cross" markrgb=".8 .8 .8"/>
    <material name="matplane" reflectance="0." texture="texplane" texrepeat="1 1" texuniform="true"/>
    <material name="obstacle" rgba="0.9 0.6 0.2 1"/>
    <material name="visualgeom" rgba="0.5 0.9 0.2 1"/>
    <mesh name="base_link" file="base_link.STL"/>
    <mesh name="left_thigh_yaw_link" file="left_thigh_yaw_link.STL"/>
    <mesh name="left_thigh_roll_link" file="left_thigh_roll_link.STL"/>
    <mesh name="left_thigh_pitch_link" file="left_thigh_pitch_link.STL"/>
    <mesh name="left_knee_link" file="left_knee_link.STL"/>
    <mesh name="left_ankle_pitch_link" file="left_ankle_pitch_link.STL"/>
    <mesh name="left_ankle_roll_link" file="left_ankle_roll_link.STL"/>
    <mesh name="right_thigh_yaw_link" file="right_thigh_yaw_link.STL"/>
    <mesh name="right_thigh_roll_link" file="right_thigh_roll_link.STL"/>
    <mesh name="right_thigh_pitch_link" file="right_thigh_pitch_link.STL"/>
    <mesh name="right_knee_link" file="right_knee_link.STL"/>
    <mesh name="right_ankle_pitch_link" file="right_ankle_pitch_link.STL"/>
    <mesh name="right_ankle_roll_link" file="right_ankle_roll_link.STL"/>
    <mesh name="torso_link" file="torso_link.STL"/>
    <mesh name="left_arm_pitch_link" file="left_arm_pitch_link.STL"/>
    <mesh name="left_arm_roll_link" file="left_arm_roll_link.STL"/>
    <mesh name="left_arm_yaw_link" file="left_arm_yaw_link.STL"/>
    <mesh name="left_elbow_pitch_link" file="left_elbow_pitch_link.STL"/>
    <mesh name="left_elbow_yaw_link" file="left_elbow_yaw_link.STL"/>
    <mesh name="right_arm_pitch_link" file="right_arm_pitch_link.STL"/>
    <mesh name="right_arm_roll_link" file="right_arm_roll_link.STL"/>
    <mesh name="right_arm_yaw_link" file="right_arm_yaw_link.STL"/>
    <mesh name="right_elbow_pitch_link" file="right_elbow_pitch_link.STL"/>
    <mesh name="right_elbow_yaw_link" file="right_elbow_yaw_link.STL"/>
    <hfield name="terrain_hfield" file="../terrain_assets/terrain_hfield.png" size="10.0 10.0 3.4 2.0"/>
  </asset>
  <worldbody>
    <light directional="true" diffuse=".4 .4 .4" specular="0.1 0.1 0.1" pos="0 0 5.0" dir="0 0 -1" castshadow="false"/>
    <light directional="true" diffuse=".6 .6 .6" specular="0.2 0.2 0.2" pos="0 0 4" dir="0 0 -1"/>
    <geom name="ground" type="hfield" hfield="terrain_hfield" pos="0 0 0" material="matplane" condim="1" conaffinity="15" group="0"/>
    <body name="base_link" pos="0 0 2.75">
      <site name="imu" size="0.01" pos="0.0 0 0.0"/>
      <inertial pos="-0.04700769 -0.00000239 -0.00862801" mass="5.51295532" fullinertia="0.03052646 0.01536233 0.03006209 0.00000063 -0.00079063 0.00000026"/>
      <joint name="floating_base_joint" type="free" limited="false"/>
      <geom type="mesh" rgba="0.75294 0.75294 0.75294 1" mesh="base_link"/>
      <body name="left_thigh_yaw_link" pos="-0.071093 0.0725 -0.051778">
        <inertial pos="-0.03847656 -0.0000142 -0.05612329" mass="1.71784575" fullinertia="0.00319789 0.0024412 0.00251651 0.00000025 -0.00065088 0.00000117"/>
        <joint name="left_thigh_yaw_joint" pos="0 0 0" axis="-0.499998 0 -0.866027" range="-1 0.2" class="leg_joint_param"/>
        <geom type="mesh" rgba="0.69804 0.69804 0.69804 1" mesh="left_thigh_yaw_link" class="visualgeom"/>
        <body name="left_thigh_roll_link" pos="-0.017693 0 -0.072346">
          <inertial pos="0.05748778 -0.00601901 -0.03308921" mass="1.66236465" fullinertia="0.00212675 0.00351120 0.00228565 0.00003170 0.00014062 -0.00001801"/>
          <joint name="left_thigh_roll_joint" pos="0 0 0" axis="0.866027 0 -0.499998" range="-0.2 2" class="leg_joint_param"/>
          <geom type="mesh" rgba="0.69804 0.69804 0.69804 1" mesh="left_thigh_roll_link" class="visualgeom"/>
          <body name="left_thigh_pitch_link" pos="0.060622 0.02085 -0.035">
            <inertial pos="0.00004587 -0.01904764 -0.19858149" mass="2.34600715" fullinertia="0.02018963 0.02158818 0.00302937 -0.00000310 0.00001430 -0.00215090"/>
            <joint name="left_thigh_pitch_joint" pos="0 0 0" axis="0 1 0" range="-2.5 0.8" class="leg_joint_param"/>
            <geom type="mesh" rgba="0.69804 0.69804 0.69804 1" mesh="left_thigh_pitch_link" class="visualgeom"/>
            <body name="left_knee_link" pos="0 0 -0.25">
              <inertial pos="-0.00035292 -0.0132798 -0.15208271" mass="1.70223945" fullinertia="0.01013470 0.00981975 0.00110105 0.00002119 0.00003224 -0.00022577"/>
              <joint name="left_knee_joint" pos="0 0 0" axis="0 1 0" range="0 2.5" class="leg_joint_param"/>
              <geom type="mesh" rgba="0.69804 0.69804 0.69804 1" mesh="left_knee_link" class="visualgeom"/>
              <body name="left_ankle_pitch_link" pos="0 -0.02085 -0.3">
                <inertial pos="0.0 0.0 0.0" mass="0.084" fullinertia="0.00000863 0.00000863 0.00001448 0.0 0.0 0.0"/>
                <joint name="left_ankle_pitch_joint" pos="0 0 0" axis="0 1 0" range="-0.6 0.6" class="leg_joint_param" frictionloss="0.05"/>
                <geom type="mesh" rgba="0.69804 0.69804 0.69804 1" mesh="left_ankle_pitch_link" class="visualgeom"/>
                <body name="left_ankle_roll_link">
                  <inertial pos="0.01454282 0.00284825 -0.02908608" mass="0.33517651" fullinertia="0.00013432 0.00054303 0.00058883 0.00001389 0.00002909 -0.00001883"/>
                  <joint name="left_ankle_roll_joint" pos="0 0 0" axis="1 0 0" range="-0.5 0.5" class="leg_joint_param" frictionloss="0.05"/>
                  <geom type="mesh" rgba="0.898039 0.917647 0.929412 1" mesh="left_ankle_roll_link"/>
                </body>
              </body>
            </body>
          </body>
        </body>
      </body>
      <body name="right_thigh_yaw_link" pos="-0.071093 -0.0725 -0.051778">
        <inertial pos="-0.03847656 0.0000142 -0.05612329" mass="1.71632614" fullinertia="0.00319396 0.0024375 0.00251592 0.0 -0.00065014 -0.00000003"/>
        <joint name="right_thigh_yaw_joint" pos="0 0 0" axis="-0.499998 0 -0.866027" range="-0.2 1" class="leg_joint_param"/>
        <geom type="mesh" rgba="0.752941 0.752941 0.752941 1" mesh="right_thigh_yaw_link" class="visualgeom"/>
        <body name="right_thigh_roll_link" pos="-0.0189924084475403 0 -0.0715958163677252">
          <inertial pos="0.05748778 0.00601901 -0.03308921" mass="1.66310652" fullinertia="0.00213051 0.00351195 0.00228331 -0.00003033 0.00013508 0.00001792"/>
          <joint name="right_thigh_roll_joint" pos="0 0 0" axis="0.866027 0 -0.499998" range="-2 0.2" class="leg_joint_param"/>
          <geom type="mesh" rgba="0.752941 0.752941 0.752941 1" mesh="right_thigh_roll_link" class="visualgeom"/>
          <body name="right_thigh_pitch_link" pos="0.0619208163652291 -0.0208499999999942 -0.0357500000093095">
            <inertial pos="0.00004587 0.01904764 -0.19858149" mass="2.34600715" fullinertia="0.02018963 0.02158818 0.00302937 0.00000309 0.00001431 0.0021509"/>
            <joint name="right_thigh_pitch_joint" pos="0 0 0" axis="0 1 0" range="-2.5 0.8" class="leg_joint_param"/>
            <geom type="mesh" rgba="0.752941 0.752941 0.752941 1" mesh="right_thigh_pitch_link" class="visualgeom"/>
            <body name="right_knee_link" pos="0 0 -0.250000000000016">
              <inertial pos="-0.00035292 0.0132798 -0.15208271" mass="1.70223945" fullinertia="0.0101347 0.00981975 0.00110105 0.00002119 -0.00003224 0.00022577"/>
              <joint name="right_knee_joint" pos="0 0 0" axis="0 1 0" range="0 2.5" class="leg_joint_param"/>
              <geom type="mesh" rgba="0.752941 0.752941 0.752941 1" mesh="right_knee_link" class="visualgeom"/>
              <body name="right_ankle_pitch_link" pos="0 0.0208500000000073 -0.299999999999986">
                <inertial pos="0 0 0" mass="0.084" fullinertia="0.00000863 0.00000863 0.00001448 0 0 0"/>
                <joint name="right_ankle_pitch_joint" pos="0 0 0" axis="0 1 0" range="-0.6 0.6" class="leg_joint_param" frictionloss="0.05"/>
                <geom type="mesh" rgba="0.752941 0.752941 0.752941 1" mesh="right_ankle_pitch_link" class="visualgeom"/>
                <body name="right_ankle_roll_link">
                  <inertial pos="0.01454282 -0.00284825 -0.02908608" mass="0.33517651" fullinertia="0.00013432 0.00054303 0.00058883 -0.00001388 0.00002909 0.00001883"/>
                  <joint name="right_ankle_roll_joint" pos="0 0 0" axis="1 0 0" range="-0.5 0.5" class="leg_joint_param" frictionloss="0.05"/>
                  <geom type="mesh" rgba="0.898039 0.917647 0.929412 1" mesh="right_ankle_roll_link"/>
                </body>
              </body>
            </body>
          </body>
        </body>
      </body>
      <body name="torso_link" pos="-0.0281649492242451 0 0.0672000000054882">
        <inertial pos="-0.00234775 -0.00000466 0.0984446" mass="7.58189737" fullinertia="0.06904132 0.05679531 0.03888628 -0.00004044 0.00223305 -0.00001881"/>
        <joint name="torso_joint" pos="0 0 0" axis="0 0 1" range="-2.62 2.62" class="waist_joint_param"/>
        <geom type="mesh" rgba="0.752941 0.752941 0.752941 1" mesh="torso_link" class="visualgeom"/>
        <body name="left_arm_pitch_link" pos="0 0.121749999999383 0.206175860782433">
          <inertial pos="-0.00436523 0.04995146 0.0" mass="0.47284363" fullinertia="0.00015644 0.00008197 0.00018907 0.00002207 0.0 0.0"/>
          <joint name="left_arm_pitch_joint" pos="0 0 0" axis="0 1 0" range="-3.14 1.57" class="arm_joint_param"/>
          <geom type="mesh" rgba="0.752941 0.752941 0.752941 1" mesh="left_arm_pitch_link" class="visualgeom"/>
          <body name="left_arm_roll_link" pos="0.02 0.056 0">
            <inertial pos="-0.0029007 0.0 -0.02197112" mass="0.08401883" fullinertia="0.00004601 0.00005649 0.00002712 0.0 -0.00001743 0.0"/>
            <joint name="left_arm_roll_joint" pos="0 0 0" axis="1 0 0" range="-0.25 3.14" class="arm_joint_param"/>
            <geom type="mesh" rgba="0.752941 0.752941 0.752941 1" mesh="left_arm_roll_link" class="visualgeom"/>
            <body name="left_arm_yaw_link" pos="-0.02 0 -0.05">
              <inertial pos="-0.00004328 -0.0018211 -0.10615895" mass="1.15324354" fullinertia="0.00619553 0.00615816 0.0003308 -0.00000002 -0.00000077 -0.0001812"/>
              <joint name="left_arm_yaw_joint" pos="0 0 0" axis="0 0 -1" range="-2.6 2.6" class="arm_joint_param"/>
              <geom type="mesh" rgba="0.752941 0.752941 0.752941 1" mesh="left_arm_yaw_link" class="visualgeom"/>
              <body name="left_elbow_pitch_link" pos="0 0.02 -0.18875">
                <inertial pos="0.02378501 -0.00433076 0.0" mass="0.09168684" fullinertia="0.00003059 0.00005023 0.00006277 0.00002004 0.0 0.0"/>
                <joint name="left_elbow_pitch_joint" pos="0 0 0" axis="0 1 0" range="-1 1.57" class="arm_joint_param"/>
                <geom type="mesh" rgba="0.752941 0.752941 0.752941 1" mesh="left_elbow_pitch_link" class="visualgeom"/>
                <body name="left_elbow_yaw_link" pos="0.05 -0.02 0">
                  <inertial pos="0.05317619 -0.0000345 -0.00001992" mass="0.68145595" fullinertia="0.00024481 0.00132562 0.00132647 -0.00000008 -0.00000014 -0.0000006"/>
                  <joint name="left_elbow_yaw_joint" pos="0 0 0" axis="1 0 0" range="-1.57 1.57" class="arm_joint_param"/>
                  <geom type="mesh" rgba="0.752941 0.752941 0.752941 1" mesh="left_elbow_yaw_link" class="visualgeom"/>
                </body>
              </body>
            </body>
          </body>
        </body>
        <body name="right_arm_pitch_link" pos="0 -0.12175 0.20518">
          <inertial pos="-0.00436523 -0.04995146 0.0" mass="0.47284363" fullinertia="0.00015644 0.00008197 0.00018907 -0.00002207 0.0 0.0"/>
          <joint name="right_arm_pitch_joint" pos="0 0 0" axis="0 1 0" range="-3.14 1.57" class="arm_joint_param"/>
          <geom type="mesh" rgba="0.752941 0.752941 0.752941 1" mesh="right_arm_pitch_link" class="visualgeom"/>
          <body name="right_arm_roll_link" pos="0.02 -0.056 0">
            <inertial pos="-0.0029007 0.0 -0.02197112" mass="0.08401883" fullinertia="0.00004601 0.00005649 0.00002712 0.0 -0.00001743 0.0"/>
            <joint name="right_arm_roll_joint" pos="0 0 0" axis="1 0 0" range="-3.14 0.25" class="arm_joint_param"/>
            <geom type="mesh" rgba="0.752941 0.752941 0.752941 1" mesh="right_arm_roll_link" class="visualgeom"/>
            <body name="right_arm_yaw_link" pos="-0.02 0 -0.05">
              <inertial pos="-0.00004328 0.0018211 -0.10615895" mass="1.15429959" fullinertia="0.0062043 0.00616498 0.00033199 0.00000007 -0.00000008 0.00017831"/>
              <joint name="right_arm_yaw_joint" pos="0 0 0" axis="0 0 -1" range="-2.6 2.6" class="arm_joint_param"/>
              <geom type="mesh" rgba="0.752941 0.752941 0.752941 1" mesh="right_arm_yaw_link" class="visualgeom"/>
              <body name="right_elbow_pitch_link" pos="0 -0.02 -0.18875">
                <inertial pos="0.02378501 0.00433076 0.0" mass="0.09168684" fullinertia="0.00003059 0.00005023 0.00006277 -0.00002004 0.0 0.0"/>
                <joint name="right_elbow_pitch_joint" pos="0 0 0" axis="0 1 0" range="-1.0 1.57" class="arm_joint_param"/>
                <geom type="mesh" rgba="0.752941 0.752941 0.752941 1" mesh="right_elbow_pitch_link" class="visualgeom"/>
                <body name="right_elbow_yaw_link" pos="0.05 0.02 0">
                  <inertial pos="0.05317619 0.0000345 -0.00001992" mass="0.68145595" fullinertia="0.00024481 0.00132562 0.00132647 0.00000008 0.00000014 -0.0000006"/>
                  <joint name="right_elbow_yaw_joint" pos="0 0 0" axis="1 0 0" range="-1.57 1.57" class="arm_joint_param"/>
                  <geom type="mesh" rgba="0.752941 0.752941 0.752941 1" mesh="right_elbow_yaw_link" class="visualgeom"/>
                </body>
              </body>
            </body>
          </body>
        </body>
      </body>
    </body>
  </worldbody>
  <actuator>
    <motor name="left_thigh_yaw_joint" joint="left_thigh_yaw_joint" gear="1" ctrllimited="true" ctrlrange="-200 200"/>
    <motor name="left_thigh_roll_joint" joint="left_thigh_roll_joint" gear="1" ctrllimited="true" ctrlrange="-200 200"/>
    <motor name="left_thigh_pitch_joint" joint="left_thigh_pitch_joint" gear="1" ctrllimited="true" ctrlrange="-200 200"/>
    <motor name="left_knee_joint" joint="left_knee_joint" gear="1" ctrllimited="true" ctrlrange="-200 200"/>
    <motor name="left_ankle_pitch_joint" joint="left_ankle_pitch_joint" gear="1" ctrllimited="true" ctrlrange="-200 200"/>
    <motor name="left_ankle_roll_joint" joint="left_ankle_roll_joint" gear="1" ctrllimited="true" ctrlrange="-200 200"/>
    <motor name="right_thigh_yaw_joint" joint="right_thigh_yaw_joint" gear="1" ctrllimited="true" ctrlrange="-200 200"/>
    <motor name="right_thigh_roll_joint" joint="right_thigh_roll_joint" gear="1" ctrllimited="true" ctrlrange="-200 200"/>
    <motor name="right_thigh_pitch_joint" joint="right_thigh_pitch_joint" gear="1" ctrllimited="true" ctrlrange="-200 200"/>
    <motor name="right_knee_joint" joint="right_knee_joint" gear="1" ctrllimited="true" ctrlrange="-200 200"/>
    <motor name="right_ankle_pitch_joint" joint="right_ankle_pitch_joint" gear="1" ctrllimited="true" ctrlrange="-200 200"/>
    <motor name="right_ankle_roll_joint" joint="right_ankle_roll_joint" gear="1" ctrllimited="true" ctrlrange="-200 200"/>
    <motor name="torso_joint" joint="torso_joint" gear="1" ctrllimited="true" ctrlrange="-200 200"/>
    <motor name="left_arm_pitch_joint" joint="left_arm_pitch_joint" gear="1" ctrllimited="true" ctrlrange="-200 200"/>
    <motor name="left_arm_roll_joint" joint="left_arm_roll_joint" gear="1" ctrllimited="true" ctrlrange="-200 200"/>
    <motor name="left_arm_yaw_joint" joint="left_arm_yaw_joint" gear="1" ctrllimited="true" ctrlrange="-200 200"/>
    <motor name="left_elbow_pitch_joint" joint="left_elbow_pitch_joint" gear="1" ctrllimited="true" ctrlrange="-200 200"/>
    <motor name="left_elbow_yaw_joint" joint="left_elbow_yaw_joint" gear="1" ctrllimited="true" ctrlrange="-200 200"/>
    <motor name="right_arm_pitch_joint" joint="right_arm_pitch_joint" gear="1" ctrllimited="true" ctrlrange="-200 200"/>
    <motor name="right_arm_roll_joint" joint="right_arm_roll_joint" gear="1" ctrllimited="true" ctrlrange="-200 200"/>
    <motor name="right_arm_yaw_joint" joint="right_arm_yaw_joint" gear="1" ctrllimited="true" ctrlrange="-200 200"/>
    <motor name="right_elbow_pitch_joint" joint="right_elbow_pitch_joint" gear="1" ctrllimited="true" ctrlrange="-200 200"/>
    <motor name="right_elbow_yaw_joint" joint="right_elbow_yaw_joint" gear="1" ctrllimited="true" ctrlrange="-200 200"/>
  </actuator>
  <sensor>
    <actuatorpos name="left_thigh_yaw_p" actuator="left_thigh_yaw_joint" user="13"/>
    <actuatorpos name="left_thigh_roll_p" actuator="left_thigh_roll_joint" user="13"/>
    <actuatorpos name="left_thigh_pitch_p" actuator="left_thigh_pitch_joint" user="13"/>
    <actuatorpos name="left_knee_p" actuator="left_knee_joint" user="13"/>
    <actuatorpos name="left_ankle_pitch_p" actuator="left_ankle_pitch_joint" user="13"/>
    <actuatorpos name="left_ankle_roll_p" actuator="left_ankle_roll_joint" user="13"/>
    <actuatorpos name="right_thigh_yaw_p" actuator="right_thigh_yaw_joint" user="13"/>
    <actuatorpos name="right_thigh_roll_p" actuator="right_thigh_roll_joint" user="13"/>
    <actuatorpos name="right_thigh_pitch_p" actuator="right_thigh_pitch_joint" user="13"/>
    <actuatorpos name="right_knee_p" actuator="right_knee_joint" user="13"/>
    <actuatorpos name="right_ankle_pitch_p" actuator="right_ankle_pitch_joint" user="13"/>
    <actuatorpos name="right_ankle_roll_p" actuator="right_ankle_roll_joint" user="13"/>
    <actuatorpos name="torso_yaw_p" actuator="torso_joint" user="13"/>
    <actuatorpos name="left_arm_pitch_p" actuator="left_arm_pitch_joint" user="13"/>
    <actuatorpos name="left_arm_roll_p" actuator="left_arm_roll_joint" user="13"/>
    <actuatorpos name="left_arm_yaw_p" actuator="left_arm_yaw_joint" user="13"/>
    <actuatorpos name="left_elbow_pitch_p" actuator="left_elbow_pitch_joint" user="13"/>
    <actuatorpos name="left_elbow_yaw_p" actuator="left_elbow_yaw_joint" user="13"/>
    <actuatorpos name="right_arm_pitch_p" actuator="right_arm_pitch_joint" user="13"/>
    <actuatorpos name="right_arm_roll_p" actuator="right_arm_roll_joint" user="13"/>
    <actuatorpos name="right_arm_yaw_p" actuator="right_arm_yaw_joint" user="13"/>
    <actuatorpos name="right_elbow_pitch_p" actuator="right_elbow_pitch_joint" user="13"/>
    <actuatorpos name="right_elbow_yaw_p" actuator="right_elbow_yaw_joint" user="13"/>
    <actuatorvel name="left_thigh_yaw_v" actuator="left_thigh_yaw_joint" user="13"/>
    <actuatorvel name="left_thigh_roll_v" actuator="left_thigh_roll_joint" user="13"/>
    <actuatorvel name="left_thigh_pitch_v" actuator="left_thigh_pitch_joint" user="13"/>
    <actuatorvel name="left_knee_v" actuator="left_knee_joint" user="13"/>
    <actuatorvel name="left_ankle_pitch_v" actuator="left_ankle_pitch_joint" user="13"/>
    <actuatorvel name="left_ankle_roll_v" actuator="left_ankle_roll_joint" user="13"/>
    <actuatorvel name="right_thigh_yaw_v" actuator="right_thigh_yaw_joint" user="13"/>
    <actuatorvel name="right_thigh_roll_v" actuator="right_thigh_roll_joint" user="13"/>
    <actuatorvel name="right_thigh_pitch_v" actuator="right_thigh_pitch_joint" user="13"/>
    <actuatorvel name="right_knee_v" actuator="right_knee_joint" user="13"/>
    <actuatorvel name="right_ankle_pitch_v" actuator="right_ankle_pitch_joint" user="13"/>
    <actuatorvel name="right_ankle_roll_v" actuator="right_ankle_roll_joint" user="13"/>
    <actuatorvel name="torso_yaw_v" actuator="torso_joint" user="13"/>
    <actuatorvel name="left_arm_pitch_v" actuator="left_arm_pitch_joint" user="13"/>
    <actuatorvel name="left_arm_roll_v" actuator="left_arm_roll_joint" user="13"/>
    <actuatorvel name="left_arm_yaw_v" actuator="left_arm_yaw_joint" user="13"/>
    <actuatorvel name="left_elbow_pitch_v" actuator="left_elbow_pitch_joint" user="13"/>
    <actuatorvel name="left_elbow_yaw_v" actuator="left_elbow_yaw_joint" user="13"/>
    <actuatorvel name="right_arm_pitch_v" actuator="right_arm_pitch_joint" user="13"/>
    <actuatorvel name="right_arm_roll_v" actuator="right_arm_roll_joint" user="13"/>
    <actuatorvel name="right_arm_yaw_v" actuator="right_arm_yaw_joint" user="13"/>
    <actuatorvel name="right_elbow_pitch_v" actuator="right_elbow_pitch_joint" user="13"/>
    <actuatorvel name="right_elbow_yaw_v" actuator="right_elbow_yaw_joint" user="13"/>
    <actuatorfrc name="left_thigh_yaw_f" actuator="left_thigh_yaw_joint" user="13" noise="1e-3"/>
    <actuatorfrc name="left_thigh_roll_f" actuator="left_thigh_roll_joint" user="13" noise="1e-3"/>
    <actuatorfrc name="left_thigh_pitch_f" actuator="left_thigh_pitch_joint" user="13" noise="1e-3"/>
    <actuatorfrc name="left_knee_f" actuator="left_knee_joint" user="13" noise="1e-3"/>
    <actuatorfrc name="left_ankle_pitch_f" actuator="left_ankle_pitch_joint" user="13" noise="1e-3"/>
    <actuatorfrc name="left_ankle_roll_f" actuator="left_ankle_roll_joint" user="13" noise="1e-3"/>
    <actuatorfrc name="right_thigh_yaw_f" actuator="right_thigh_yaw_joint" user="13" noise="1e-3"/>
    <actuatorfrc name="right_thigh_roll_f" actuator="right_thigh_roll_joint" user="13" noise="1e-3"/>
    <actuatorfrc name="right_thigh_pitch_f" actuator="right_thigh_pitch_joint" user="13" noise="1e-3"/>
    <actuatorfrc name="right_knee_f" actuator="right_knee_joint" user="13" noise="1e-3"/>
    <actuatorfrc name="right_ankle_pitch_f" actuator="right_ankle_pitch_joint" user="13" noise="1e-3"/>
    <actuatorfrc name="right_ankle_roll_f" actuator="right_ankle_roll_joint" user="13" noise="1e-3"/>
    <actuatorfrc name="torso_yaw_f" actuator="torso_joint" user="13" noise="1e-3"/>
    <actuatorfrc name="left_arm_pitch_f" actuator="left_arm_pitch_joint" user="13" noise="1e-3"/>
    <actuatorfrc name="left_arm_roll_f" actuator="left_arm_roll_joint" user="13" noise="1e-3"/>
    <actuatorfrc name="left_arm_yaw_f" actuator="left_arm_yaw_joint" user="13" noise="1e-3"/>
    <actuatorfrc name="left_elbow_pitch_f" actuator="left_elbow_pitch_joint" user="13" noise="1e-3"/>
    <actuatorfrc name="left_elbow_yaw_f" actuator="left_elbow_yaw_joint" user="13" noise="1e-3"/>
    <actuatorfrc name="right_arm_pitch_f" actuator="right_arm_pitch_joint" user="13" noise="1e-3"/>
    <actuatorfrc name="right_arm_roll_f" actuator="right_arm_roll_joint" user="13" noise="1e-3"/>
    <actuatorfrc name="right_arm_yaw_f" actuator="right_arm_yaw_joint" user="13" noise="1e-3"/>
    <actuatorfrc name="right_elbow_pitch_f" actuator="right_elbow_pitch_joint" user="13" noise="1e-3"/>
    <actuatorfrc name="right_elbow_yaw_f" actuator="right_elbow_yaw_joint" user="13" noise="1e-3"/>
    <framequat name="orientation" objtype="site" noise="0.001" objname="imu"/>
    <framepos name="position" objtype="site" noise="0.001" objname="imu"/>
    <gyro name="angular-velocity" site="imu" noise="0.005" cutoff="34.9"/>
    <velocimeter name="linear-velocity" site="imu" noise="0.001" cutoff="30"/>
    <accelerometer name="linear-acceleration" site="imu" noise="0.005" cutoff="157"/>
    <magnetometer name="magnetometer" site="imu"/>
  </sensor>
  <visual>
    <global offwidth="1920" offheight="1080"/>
  </visual>
</mujoco>
